Workbook

Sheet README
A1: FRC Peachtree District (PCH) — 2027 Competitive Outlook
A2: Rebuilt for the 2027 season from the 2025-based 2026 outlook, updated with official 2026 results. Built Sept 23, 2026.
A4: WHAT CHANGED FOR 2027
A5: • Columbus (GACOL) is not on the 2027 schedule. A new PCH District Douglasville Event (GADOU) takes Week 5.
A6: • Weeks reshuffled: Dalton W1, Gainesville W2 (was W5), Gwinnett W3 (was W2), Albany W4, Douglasville W5, DCMP at Mercer W6 (Apr 7–9).
A7: • Posted capacities total 149 team-slots (30/30/30/29/30). 74 active PCH teams × 2 events = 148, so every event is forecast to run essentially full.
A9: SHEETS
A10: Recommendation — the final Round 1 and Round 2 preference lists for 3329, the outcome of each lottery result, and the bottom line. Numbers link live to the planner.
A11: Assumptions — every weight and coefficient the formulas use (yellow cells are levers you can change), followed from row 37 by a numbered, plain-language list of every assumption behind the predictions: what it is, what it rests on, and what happens if it is wrong.
A12: Events 2027 — forecast attendance and competitive density per event, with the 2026 actual density alongside.
A13: Forecast 2027 — predicted two events for all 74 teams. Event codes in blue are editable: change one and every density/planner figure recalculates.
A14: Fields 2027 — team-by-event matrix of predicted fields, shaded by strength (red ≥ 70, orange 45–70, yellow below 45).
... A41: Original workbook: FRC_2026_Competitive_Outlook.xls (2022–2025 venue history, 2026 predictions, drive-time data).

Sheet Recommendation
A1: 3329 Wildbots: final 2027 event-selection recommendation
A2: Goal: the most district points toward DCMP qualification, with at least 7 clear days to rebuild before the second event and before the District Championship in Macon. Assumptions behind every number: Assumptions sheet, rows 37 onward.
A4: Round 1 preference list (enter Sep 24 – Oct 1, 2026, noon ET)
A5: Rank | B5: Event | C5: Week and dates | D5: Why
A6: 1 | B6: Albany (GAALB) | C6: Week 4, Mar 25–27 | D6: In both of the best plans; smallest capacity (29, forecast 28), so the scarcest slot; shortest drive from Kingsland (3.1 h).
A7: 2 | B7: Dalton (GADAL) | C7: Week 1, Mar 4–6 | D7: Pairs with Albany (18 days apart) or Gwinnett (12 days apart), so a rule-passing Round 2 option remains even if Albany is lost.
A8: 3 | B8: Gainesville (GAGAI) | C8: Week 2, Mar 11–13 | D8: In the best pair, but its only rule-passing partner is Albany.
A9: 4 | B9: Gwinnett (GAGWI) | C9: Week 3, Mar 19–21 | D9: Keeps the team placed rather than waitlisted.
A10: Do not list | B10: Douglasville (GADOU) | C10: Week 5, Apr 1–3 | D10: Ends Apr 3, four days before DCMP: breaks the Macon rule.
A12: Round 2 preference list (enter Oct 15 – 22, 2026, noon ET), ranked by where Round 1 places us
A13: Round 1 placement | B13: Round 2 rank | C13: Event | D13: Expected pre-DCMP points | E13: Chance of making cut | F13: Days between events | G13: Days before DCMP | H13: Note
A14: Albany | B14: 1 | C14: Gainesville | D14: =INDEX('Planner 3329'!$H$22:$H$31,MATCH("GAGAI+GAALB",'Planner 3329'!$Q$22:$Q$31,0)) -> 66.168097 | E14: =INDEX('Planner 3329'!$O$22:$O$31,MATCH("GAGAI+GAALB",'Planner 3329'!$Q$22:$Q$31,0)) -> 0.85101301 | F14: 11 | G14: 10 | H14: Target outcome
A15: Albany | B15: 2 | C15: Dalton | D15: =INDEX('Planner 3329'!$H$22:$H$31,MATCH("GADAL+GAALB",'Planner 3329'!$Q$22:$Q$31,0)) -> 64.464849 | E15: =INDEX('Planner 3329'!$O$22:$O$31,MATCH("GADAL+GAALB",'Planner 3329'!$Q$22:$Q$31,0)) -> 0.82411068 | F15: 18 | G15: 10 | H15: Passes both rules
A16: Albany | B16: 3 | C16: Gwinnett | D16: =INDEX('Planner 3329'!$H$22:$H$31,MATCH("GAGWI+GAALB",'Planner 3329'!$Q$22:$Q$31,0)) -> 64.464849 | E16: =INDEX('Planner 3329'!$O$22:$O$31,MATCH("GAGWI+GAALB",'Planner 3329'!$Q$22:$Q$31,0)) -> 0.82411068 | F16: 3 | G16: 10 | H16: Last resort: breaks rebuild rule
A17: Albany | B17: Do not list | C17: Douglasville | D17: =INDEX('Planner 3329'!$H$22:$H$31,MATCH("GAALB+GADOU",'Planner 3329'!$Q$22:$Q$31,0)) -> 72.401829 | E17: =INDEX('Planner 3329'!$O$22:$O$31,MATCH("GAALB+GADOU",'Planner 3329'!$Q$22:$Q$31,0)) -> 0.92535891 | F17: 4 | G17: 3 | H17: Breaks both rules
A18: Dalton | B18: 1 | C18: Albany | D18: =INDEX('Planner 3329'!$H$22:$H$31,MATCH("GADAL+GAALB",'Planner 3329'!$Q$22:$Q$31,0)) -> 64.464849 | E18: =INDEX('Planner 3329'!$O$22:$O$31,MATCH("GADAL+GAALB",'Planner 3329'!$Q$22:$Q$31,0)) -> 0.82411068 | F18: 18 | G18: 10 | H18: Passes both rules
A19: Dalton | B19: 2 | C19: Gwinnett | D19: =INDEX('Planner 3329'!$H$22:$H$31,MATCH("GADAL+GAGWI",'Planner 3329'!$Q$22:$Q$31,0)) -> 60.895905 | E19: =INDEX('Planner 3329'!$O$22:$O$31,MATCH("GADAL+GAGWI",'Planner 3329'!$Q$22:$Q$31,0)) -> 0.75847373 | F19: 12 | G19: 16 | H19: Passes both rules
A20: Dalton | B20: 3 | C20: Gainesville | D20: =INDEX('Planner 3329'!$H$22:$H$31,MATCH("GADAL+GAGAI",'Planner 3329'!$Q$22:$Q$31,0)) -> 62.599152 | E20: =INDEX('Planner 3329'!$O$22:$O$31,MATCH("GADAL+GAGAI",'Planner 3329'!$Q$22:$Q$31,0)) -> 0.79132993 | F20: 4 | G20: 16 | H20: Breaks rebuild rule
A21: Dalton | B21: 4 | C21: Douglasville | D21: =INDEX('Planner 3329'!$H$22:$H$31,MATCH("GADAL+GADOU",'Planner 3329'!$Q$22:$Q$31,0)) -> 68.832884 | E21: =INDEX('Planner 3329'!$O$22:$O$31,MATCH("GADAL+GADOU",'Planner 3329'!$Q$22:$Q$31,0)) -> 0.8873066 | F21: 25 | G21: 3 | H21: Breaks Macon rule
A22: Gainesville | B22: 1 | C22: Albany | D22: =INDEX('Planner 3329'!$H$22:$H$31,MATCH("GAGAI+GAALB",'Planner 3329'!$Q$22:$Q$31,0)) -> 66.168097 | E22: =INDEX('Planner 3329'!$O$22:$O$31,MATCH("GAGAI+GAALB",'Planner 3329'!$Q$22:$Q$31,0)) -> 0.85101301 | F22: 11 | G22: 10 | H22: Target outcome
A23: Gainesville | B23: 2 | C23: Dalton | D23: =INDEX('Planner 3329'!$H$22:$H$31,MATCH("GADAL+GAGAI",'Planner 3329'!$Q$22:$Q$31,0)) -> 62.599152 | E23: =INDEX('Planner 3329'!$O$22:$O$31,MATCH("GADAL+GAGAI",'Planner 3329'!$Q$22:$Q$31,0)) -> 0.79132993 | F23: 4 | G23: 16 | H23: Breaks rebuild rule
A24: Gainesville | B24: 3 | C24: Gwinnett | D24: =INDEX('Planner 3329'!$H$22:$H$31,MATCH("GAGAI+GAGWI",'Planner 3329'!$Q$22:$Q$31,0)) -> 62.599152 | E24: =INDEX('Planner 3329'!$O$22:$O$31,MATCH("GAGAI+GAGWI",'Planner 3329'!$Q$22:$Q$31,0)) -> 0.79132993 | F24: 5 | G24: 16 | H24: Breaks rebuild rule
A25: Gainesville | B25: 4 | C25: Douglasville | D25: =INDEX('Planner 3329'!$H$22:$H$31,MATCH("GAGAI+GADOU",'Planner 3329'!$Q$22:$Q$31,0)) -> 70.536132 | E25: =INDEX('Planner 3329'!$O$22:$O$31,MATCH("GAGAI+GADOU",'Planner 3329'!$Q$22:$Q$31,0)) -> 0.90691113 | F25: 18 | G25: 3 | H25: Breaks Macon rule
A27: Outcome by lottery result
A28: Round 1 / Round 2 result | B28: Events | C28: Expected pre-DCMP points | D28: Chance of making cut | E28: Bad-luck total (1 in 10)
A29: ='Planner 3329'!A39 -> First choice / first choice | B29: ='Planner 3329'!B39 -> Albany + Gainesville | C29: ='Planner 3329'!C39 -> 66.168097 | D29: ='Planner 3329'!D39 -> 0.85101301 | E29: ='Planner 3329'!E39 -> 46.634628
A30: ='Planner 3329'!A40 -> First choice / second choice | B30: ='Planner 3329'!B40 -> Albany + Dalton | C30: ='Planner 3329'!C40 -> 64.464849 | D30: ='Planner 3329'!D40 -> 0.82411068 | E30: ='Planner 3329'!E40 -> 44.93138
A31: ='Planner 3329'!A41 -> Second choice / first choice | B31: ='Planner 3329'!B41 -> Dalton + Albany | C31: ='Planner 3329'!C41 -> 64.464849 | D31: ='Planner 3329'!D41 -> 0.82411068 | E31: ='Planner 3329'!E41 -> 44.93138
A32: ='Planner 3329'!A42 -> Second choice / second choice | B32: ='Planner 3329'!B42 -> Dalton + Gwinnett | C32: ='Planner 3329'!C42 -> 60.895905 | D32: ='Planner 3329'!D42 -> 0.75847373 | E32: ='Planner 3329'!E42 -> 41.362435
A34: Bottom line
A35: Target: Gainesville (W2) + Albany (W4), about 66 expected points, 11 days between events, 10 days before Macon, 16.6 h round-trip driving.
A36: Every recommended outcome clears the ~50-point cut on expected points; the worst rule-passing outcome, Dalton + Gwinnett (second choice in both rounds), still has roughly a three-in-four chance.
A37: Enter a full ranked list in each round so the team is placed rather than waitlisted; every event is forecast near capacity.
A38: Confirm with GeorgiaFIRST whether PCH uses a home-event system before submitting.
A40: Points and chances link live to Planner 3329 and are valid while the focus team on Assumptions (B20) is 3329. Days between events and before DCMP are calendar facts from the 2027 schedule.

Sheet Planner 3329
A1: Event planner — maximize district points to qualify for DCMP
A3: Focus team | B3: =Assumptions!B20 -> 3329
A4: Name | B4: =INDEX(Strength!$B$2:$B$76,MATCH(B3,Strength!$A$2:$A$76,0)) -> Wildbots
A5: Home city | B5: =INDEX(Strength!$C$2:$C$76,MATCH(B3,Strength!$A$2:$A$76,0)) -> Kingsland
A6: 2026 blended strength | B6: =INDEX(Strength!$U$2:$U$76,MATCH(B3,Strength!$A$2:$A$76,0)) -> 39.720696
A7: 2026 strength rank (of 74) | B7: =INDEX(Strength!$V$2:$V$76,MATCH(B3,Strength!$A$2:$A$76,0)) -> 26
A8: 2026 pre-DCMP points | B8: =INDEX(Strength!$G$2:$G$76,MATCH(B3,Strength!$A$2:$A$76,0))+INDEX(Strength!$I$2:$I$76,MATCH(B3,Strength!$A$2:$A$76,0))+INDEX(Strength!$J$2:$J$76,MATCH(B3,Strength!$A$2:$A$76,0)) -> 64
A9: Forecast 2027 events | B9: =IF(ISERROR(INDEX('Forecast 2027'!$F$2:$F$76,MATCH(B3,'Forecast 2027'!$A$2:$A$76,0))&" + "&INDEX('Forecast 2027'!$G$2:$G$76,MATCH(B3,'Forecast 2027'!$A$2:$A$76,0))),"",INDEX('Forecast 2027'!$F$2:$F$76,MATCH(B3,'Forecast 2027'!$A$2:$A$76,0))&" + "&INDEX('Forecast 2027'!$G$2:$G$76,MATCH(B3,'Forecast 2027'!$A$2:$A$76,0))) -> GADAL + GAALB
A10: DCMP cut / safe target | B10: =Assumptions!B13&" / "&Assumptions!B14 -> 50 / 60
A12: Per-event outlook
A13: Code | B13: City | C13: Week | D13: Drive (h, one way) | E13: Forecast field size | F13: Stronger teams forecast (k) | G13: Expected district pts | H13: Top-10 teams there
A14: GADAL | B14: Dalton | C14: 1 | D14: =IF(ISERROR(INDEX('Drive Times'!$D$12:$I$51,MATCH($B$5,'Drive Times'!$A$12:$A$51,0),MATCH(A14,'Drive Times'!$D$11:$I$11,0))),"",INDEX('Drive Times'!$D$12:$I$51,MATCH($B$5,'Drive Times'!$A$12:$A$51,0),MATCH(A14,'Drive Times'!$D$11:$I$11,0))) -> 6.3482046 | E14: =INDEX('Events 2027'!$G$5:$G$9,MATCH(A14,'Events 2027'!$A$5:$A$9,0)) -> 30 | F14: =SUMPRODUCT(('Forecast 2027'!$F$2:$F$75=A14)*('Forecast 2027'!$D$2:$D$75>$B$6))+SUMPRODUCT(('Forecast 2027'!$G$2:$G$75=A14)*('Forecast 2027'!$D$2:$D$75>$B$6)) -> 11 | G14: =MAX(0,Assumptions!$B$9+Assumptions!$B$10*LN(1+F14)) -> 30.447952 | H14: =INDEX('Events 2027'!$I$5:$I$9,MATCH(A14,'Events 2027'!$A$5:$A$9,0)) -> 5
A15: GAGAI | B15: Gainesville | C15: 2 | D15: =IF(ISERROR(INDEX('Drive Times'!$D$12:$I$51,MATCH($B$5,'Drive Times'!$A$12:$A$51,0),MATCH(A15,'Drive Times'!$D$11:$I$11,0))),"",INDEX('Drive Times'!$D$12:$I$51,MATCH($B$5,'Drive Times'!$A$12:$A$51,0),MATCH(A15,'Drive Times'!$D$11:$I$11,0))) -> 5.2085707 | E15: =INDEX('Events 2027'!$G$5:$G$9,MATCH(A15,'Events 2027'!$A$5:$A$9,0)) -> 30 | F15: =SUMPRODUCT(('Forecast 2027'!$F$2:$F$75=A15)*('Forecast 2027'!$D$2:$D$75>$B$6))+SUMPRODUCT(('Forecast 2027'!$G$2:$G$75=A15)*('Forecast 2027'!$D$2:$D$75>$B$6)) -> 10 | G15: =MAX(0,Assumptions!$B$9+Assumptions!$B$10*LN(1+F15)) -> 32.1512 | H15: =INDEX('Events 2027'!$I$5:$I$9,MATCH(A15,'Events 2027'!$A$5:$A$9,0)) -> 3
A16: GAGWI | B16: Lawrenceville | C16: 3 | D16: =IF(ISERROR(INDEX('Drive Times'!$D$12:$I$51,MATCH($B$5,'Drive Times'!$A$12:$A$51,0),MATCH(A16,'Drive Times'!$D$11:$I$11,0))),"",INDEX('Drive Times'!$D$12:$I$51,MATCH($B$5,'Drive Times'!$A$12:$A$51,0),MATCH(A16,'Drive Times'!$D$11:$I$11,0))) -> 4.9192408 | E16: =INDEX('Events 2027'!$G$5:$G$9,MATCH(A16,'Events 2027'!$A$5:$A$9,0)) -> 30 | F16: =SUMPRODUCT(('Forecast 2027'!$F$2:$F$75=A16)*('Forecast 2027'!$D$2:$D$75>$B$6))+SUMPRODUCT(('Forecast 2027'!$G$2:$G$75=A16)*('Forecast 2027'!$D$2:$D$75>$B$6)) -> 11 | G16: =MAX(0,Assumptions!$B$9+Assumptions!$B$10*LN(1+F16)) -> 30.447952 | H16: =INDEX('Events 2027'!$I$5:$I$9,MATCH(A16,'Events 2027'!$A$5:$A$9,0)) -> 4
A17: GAALB | B17: Albany | C17: 4 | D17: =IF(ISERROR(INDEX('Drive Times'!$D$12:$I$51,MATCH($B$5,'Drive Times'!$A$12:$A$51,0),MATCH(A17,'Drive Times'!$D$11:$I$11,0))),"",INDEX('Drive Times'!$D$12:$I$51,MATCH($B$5,'Drive Times'!$A$12:$A$51,0),MATCH(A17,'Drive Times'!$D$11:$I$11,0))) -> 3.0748738 | E17: =INDEX('Events 2027'!$G$5:$G$9,MATCH(A17,'Events 2027'!$A$5:$A$9,0)) -> 28 | F17: =SUMPRODUCT(('Forecast 2027'!$F$2:$F$75=A17)*('Forecast 2027'!$D$2:$D$75>$B$6))+SUMPRODUCT(('Forecast 2027'!$G$2:$G$75=A17)*('Forecast 2027'!$D$2:$D$75>$B$6)) -> 9 | G17: =MAX(0,Assumptions!$B$9+Assumptions!$B$10*LN(1+F17)) -> 34.016897 | H17: =INDEX('Events 2027'!$I$5:$I$9,MATCH(A17,'Events 2027'!$A$5:$A$9,0)) -> 5
A18: GADOU | B18: Douglasville | C18: 5 | D18: =IF(ISERROR(INDEX('Drive Times'!$D$12:$I$51,MATCH($B$5,'Drive Times'!$A$12:$A$51,0),MATCH(A18,'Drive Times'!$D$11:$I$11,0))),"",INDEX('Drive Times'!$D$12:$I$51,MATCH($B$5,'Drive Times'!$A$12:$A$51,0),MATCH(A18,'Drive Times'!$D$11:$I$11,0))) -> 5.194994 | E18: =INDEX('Events 2027'!$G$5:$G$9,MATCH(A18,'Events 2027'!$A$5:$A$9,0)) -> 30 | F18: =SUMPRODUCT(('Forecast 2027'!$F$2:$F$75=A18)*('Forecast 2027'!$D$2:$D$75>$B$6))+SUMPRODUCT(('Forecast 2027'!$G$2:$G$75=A18)*('Forecast 2027'!$D$2:$D$75>$B$6)) -> 7 | G18: =MAX(0,Assumptions!$B$9+Assumptions!$B$10*LN(1+F18)) -> 38.384932 | H18: =INDEX('Events 2027'!$I$5:$I$9,MATCH(A18,'Events 2027'!$A$5:$A$9,0)) -> 3
A20: All two-event combinations
A21: Event 1 | B21: Event 2 | C21: Week 1 | D21: Week 2 | E21: Gap (wks) | F21: Pts event 1 | G21: Pts event 2 | H21: Expected pre-DCMP pts | I21: Round-trip drive (h) | J21: Margin vs cut | K21: Outlook | L21: Points rank | M21: Schedule note | N21: Pts if gap ≥ 2 | O21: Chance of making cut | P21: Bad-luck total (1 in 10) | Q21: Pair key
A22: GADAL | B22: GAGAI | C22: =INDEX($C$14:$C$18,MATCH(A22,$A$14:$A$18,0)) -> 1 | D22: =INDEX($C$14:$C$18,MATCH(B22,$A$14:$A$18,0)) -> 2 | E22: =ABS(D22-C22) -> 1 | F22: =INDEX($G$14:$G$18,MATCH(A22,$A$14:$A$18,0)) -> 30.447952 | G22: =INDEX($G$14:$G$18,MATCH(B22,$A$14:$A$18,0)) -> 32.1512 | H22: =F22+G22 -> 62.599152 | I22: =2*(INDEX($D$14:$D$18,MATCH(A22,$A$14:$A$18,0))+INDEX($D$14:$D$18,MATCH(B22,$A$14:$A$18,0))) -> 23.113551 | J22: =H22-Assumptions!$B$13 -> 12.599152 | K22: =IF(H22>=Assumptions!$B$14,"Safe",IF(H22>=Assumptions!$B$13,"Borderline","At risk")) -> Safe | L22: =RANK(H22,$H$22:$H$31)+COUNTIF($H$22:H22,H22)-1 -> 8 | M22: =IF(E22=1,"Back-to-back weeks",IF(E22>=4,"Long gap","")) -> Back-to-back weeks | N22: =IF(E22>=2,H22,-1) -> -1 | O22: =1-NORMDIST(Assumptions!$B$13,H22,Assumptions!$B$33,1) -> 0.79132993 | P22: =NORMINV(0.1,H22,Assumptions!$B$34) -> 43.065683 | Q22: =A22&"+"&B22 -> GADAL+GAGAI
A23: GADAL | B23: GAGWI | C23: =INDEX($C$14:$C$18,MATCH(A23,$A$14:$A$18,0)) -> 1 | D23: =INDEX($C$14:$C$18,MATCH(B23,$A$14:$A$18,0)) -> 3 | E23: =ABS(D23-C23) -> 2 | F23: =INDEX($G$14:$G$18,MATCH(A23,$A$14:$A$18,0)) -> 30.447952 | G23: =INDEX($G$14:$G$18,MATCH(B23,$A$14:$A$18,0)) -> 30.447952 | H23: =F23+G23 -> 60.895905 | I23: =2*(INDEX($D$14:$D$18,MATCH(A23,$A$14:$A$18,0))+INDEX($D$14:$D$18,MATCH(B23,$A$14:$A$18,0))) -> 22.534891 | J23: =H23-Assumptions!$B$13 -> 10.895905 | K23: =IF(H23>=Assumptions!$B$14,"Safe",IF(H23>=Assumptions!$B$13,"Borderline","At risk")) -> Safe | L23: =RANK(H23,$H$22:$H$31)+COUNTIF($H$22:H23,H23)-1 -> 10 | M23: =IF(E23=1,"Back-to-back weeks",IF(E23>=4,"Long gap","")) | N23: =IF(E23>=2,H23,-1) -> 60.895905 | O23: =1-NORMDIST(Assumptions!$B$13,H23,Assumptions!$B$33,1) -> 0.75847373 | P23: =NORMINV(0.1,H23,Assumptions!$B$34) -> 41.362435 | Q23: =A23&"+"&B23 -> GADAL+GAGWI
A24: GADAL | B24: GAALB | C24: =INDEX($C$14:$C$18,MATCH(A24,$A$14:$A$18,0)) -> 1 | D24: =INDEX($C$14:$C$18,MATCH(B24,$A$14:$A$18,0)) -> 4 | E24: =ABS(D24-C24) -> 3 | F24: =INDEX($G$14:$G$18,MATCH(A24,$A$14:$A$18,0)) -> 30.447952 | G24: =INDEX($G$14:$G$18,MATCH(B24,$A$14:$A$18,0)) -> 34.016897 | H24: =F24+G24 -> 64.464849 | I24: =2*(INDEX($D$14:$D$18,MATCH(A24,$A$14:$A$18,0))+INDEX($D$14:$D$18,MATCH(B24,$A$14:$A$18,0))) -> 18.846157 | J24: =H24-Assumptions!$B$13 -> 14.464849 | K24: =IF(H24>=Assumptions!$B$14,"Safe",IF(H24>=Assumptions!$B$13,"Borderline","At risk")) -> Safe | L24: =RANK(H24,$H$22:$H$31)+COUNTIF($H$22:H24,H24)-1 -> 6 | M24: =IF(E24=1,"Back-to-back weeks",IF(E24>=4,"Long gap","")) | N24: =IF(E24>=2,H24,-1) -> 64.464849 | O24: =1-NORMDIST(Assumptions!$B$13,H24,Assumptions!$B$33,1) -> 0.82411068 | P24: =NORMINV(0.1,H24,Assumptions!$B$34) -> 44.93138 | Q24: =A24&"+"&B24 -> GADAL+GAALB
A25: GADAL | B25: GADOU | C25: =INDEX($C$14:$C$18,MATCH(A25,$A$14:$A$18,0)) -> 1 | D25: =INDEX($C$14:$C$18,MATCH(B25,$A$14:$A$18,0)) -> 5 | E25: =ABS(D25-C25) -> 4 | F25: =INDEX($G$14:$G$18,MATCH(A25,$A$14:$A$18,0)) -> 30.447952 | G25: =INDEX($G$14:$G$18,MATCH(B25,$A$14:$A$18,0)) -> 38.384932 | H25: =F25+G25 -> 68.832884 | I25: =2*(INDEX($D$14:$D$18,MATCH(A25,$A$14:$A$18,0))+INDEX($D$14:$D$18,MATCH(B25,$A$14:$A$18,0))) -> 23.086397 | J25: =H25-Assumptions!$B$13 -> 18.832884 | K25: =IF(H25>=Assumptions!$B$14,"Safe",IF(H25>=Assumptions!$B$13,"Borderline","At risk")) -> Safe | L25: =RANK(H25,$H$22:$H$31)+COUNTIF($H$22:H25,H25)-1 -> 3 | M25: =IF(E25=1,"Back-to-back weeks",IF(E25>=4,"Long gap","")) -> Long gap | N25: =IF(E25>=2,H25,-1) -> 68.832884 | O25: =1-NORMDIST(Assumptions!$B$13,H25,Assumptions!$B$33,1) -> 0.8873066 | P25: =NORMINV(0.1,H25,Assumptions!$B$34) -> 49.299415 | Q25: =A25&"+"&B25 -> GADAL+GADOU
A26: GAGAI | B26: GAGWI | C26: =INDEX($C$14:$C$18,MATCH(A26,$A$14:$A$18,0)) -> 2 | D26: =INDEX($C$14:$C$18,MATCH(B26,$A$14:$A$18,0)) -> 3 | E26: =ABS(D26-C26) -> 1 | F26: =INDEX($G$14:$G$18,MATCH(A26,$A$14:$A$18,0)) -> 32.1512 | G26: =INDEX($G$14:$G$18,MATCH(B26,$A$14:$A$18,0)) -> 30.447952 | H26: =F26+G26 -> 62.599152 | I26: =2*(INDEX($D$14:$D$18,MATCH(A26,$A$14:$A$18,0))+INDEX($D$14:$D$18,MATCH(B26,$A$14:$A$18,0))) -> 20.255623 | J26: =H26-Assumptions!$B$13 -> 12.599152 | K26: =IF(H26>=Assumptions!$B$14,"Safe",IF(H26>=Assumptions!$B$13,"Borderline","At risk")) -> Safe | L26: =RANK(H26,$H$22:$H$31)+COUNTIF($H$22:H26,H26)-1 -> 9 | M26: =IF(E26=1,"Back-to-back weeks",IF(E26>=4,"Long gap","")) -> Back-to-back weeks | N26: =IF(E26>=2,H26,-1) -> -1 | O26: =1-NORMDIST(Assumptions!$B$13,H26,Assumptions!$B$33,1) -> 0.79132993 | P26: =NORMINV(0.1,H26,Assumptions!$B$34) -> 43.065683 | Q26: =A26&"+"&B26 -> GAGAI+GAGWI
A27: GAGAI | B27: GAALB | C27: =INDEX($C$14:$C$18,MATCH(A27,$A$14:$A$18,0)) -> 2 | D27: =INDEX($C$14:$C$18,MATCH(B27,$A$14:$A$18,0)) -> 4 | E27: =ABS(D27-C27) -> 2 | F27: =INDEX($G$14:$G$18,MATCH(A27,$A$14:$A$18,0)) -> 32.1512 | G27: =INDEX($G$14:$G$18,MATCH(B27,$A$14:$A$18,0)) -> 34.016897 | H27: =F27+G27 -> 66.168097 | I27: =2*(INDEX($D$14:$D$18,MATCH(A27,$A$14:$A$18,0))+INDEX($D$14:$D$18,MATCH(B27,$A$14:$A$18,0))) -> 16.566889 | J27: =H27-Assumptions!$B$13 -> 16.168097 | K27: =IF(H27>=Assumptions!$B$14,"Safe",IF(H27>=Assumptions!$B$13,"Borderline","At risk")) -> Safe | L27: =RANK(H27,$H$22:$H$31)+COUNTIF($H$22:H27,H27)-1 -> 5 | M27: =IF(E27=1,"Back-to-back weeks",IF(E27>=4,"Long gap","")) | N27: =IF(E27>=2,H27,-1) -> 66.168097 | O27: =1-NORMDIST(Assumptions!$B$13,H27,Assumptions!$B$33,1) -> 0.85101301 | P27: =NORMINV(0.1,H27,Assumptions!$B$34) -> 46.634628 | Q27: =A27&"+"&B27 -> GAGAI+GAALB
A28: GAGAI | B28: GADOU | C28: =INDEX($C$14:$C$18,MATCH(A28,$A$14:$A$18,0)) -> 2 | D28: =INDEX($C$14:$C$18,MATCH(B28,$A$14:$A$18,0)) -> 5 | E28: =ABS(D28-C28) -> 3 | F28: =INDEX($G$14:$G$18,MATCH(A28,$A$14:$A$18,0)) -> 32.1512 | G28: =INDEX($G$14:$G$18,MATCH(B28,$A$14:$A$18,0)) -> 38.384932 | H28: =F28+G28 -> 70.536132 | I28: =2*(INDEX($D$14:$D$18,MATCH(A28,$A$14:$A$18,0))+INDEX($D$14:$D$18,MATCH(B28,$A$14:$A$18,0))) -> 20.807129 | J28: =H28-Assumptions!$B$13 -> 20.536132 | K28: =IF(H28>=Assumptions!$B$14,"Safe",IF(H28>=Assumptions!$B$13,"Borderline","At risk")) -> Safe | L28: =RANK(H28,$H$22:$H$31)+COUNTIF($H$22:H28,H28)-1 -> 2 | M28: =IF(E28=1,"Back-to-back weeks",IF(E28>=4,"Long gap","")) | N28: =IF(E28>=2,H28,-1) -> 70.536132 | O28: =1-NORMDIST(Assumptions!$B$13,H28,Assumptions!$B$33,1) -> 0.90691113 | P28: =NORMINV(0.1,H28,Assumptions!$B$34) -> 51.002663 | Q28: =A28&"+"&B28 -> GAGAI+GADOU
A29: GAGWI | B29: GAALB | C29: =INDEX($C$14:$C$18,MATCH(A29,$A$14:$A$18,0)) -> 3 | D29: =INDEX($C$14:$C$18,MATCH(B29,$A$14:$A$18,0)) -> 4 | E29: =ABS(D29-C29) -> 1 | F29: =INDEX($G$14:$G$18,MATCH(A29,$A$14:$A$18,0)) -> 30.447952 | G29: =INDEX($G$14:$G$18,MATCH(B29,$A$14:$A$18,0)) -> 34.016897 | H29: =F29+G29 -> 64.464849 | I29: =2*(INDEX($D$14:$D$18,MATCH(A29,$A$14:$A$18,0))+INDEX($D$14:$D$18,MATCH(B29,$A$14:$A$18,0))) -> 15.988229 | J29: =H29-Assumptions!$B$13 -> 14.464849 | K29: =IF(H29>=Assumptions!$B$14,"Safe",IF(H29>=Assumptions!$B$13,"Borderline","At risk")) -> Safe | L29: =RANK(H29,$H$22:$H$31)+COUNTIF($H$22:H29,H29)-1 -> 7 | M29: =IF(E29=1,"Back-to-back weeks",IF(E29>=4,"Long gap","")) -> Back-to-back weeks | N29: =IF(E29>=2,H29,-1) -> -1 | O29: =1-NORMDIST(Assumptions!$B$13,H29,Assumptions!$B$33,1) -> 0.82411068 | P29: =NORMINV(0.1,H29,Assumptions!$B$34) -> 44.93138 | Q29: =A29&"+"&B29 -> GAGWI+GAALB
A30: GAGWI | B30: GADOU | C30: =INDEX($C$14:$C$18,MATCH(A30,$A$14:$A$18,0)) -> 3 | D30: =INDEX($C$14:$C$18,MATCH(B30,$A$14:$A$18,0)) -> 5 | E30: =ABS(D30-C30) -> 2 | F30: =INDEX($G$14:$G$18,MATCH(A30,$A$14:$A$18,0)) -> 30.447952 | G30: =INDEX($G$14:$G$18,MATCH(B30,$A$14:$A$18,0)) -> 38.384932 | H30: =F30+G30 -> 68.832884 | I30: =2*(INDEX($D$14:$D$18,MATCH(A30,$A$14:$A$18,0))+INDEX($D$14:$D$18,MATCH(B30,$A$14:$A$18,0))) -> 20.22847 | J30: =H30-Assumptions!$B$13 -> 18.832884 | K30: =IF(H30>=Assumptions!$B$14,"Safe",IF(H30>=Assumptions!$B$13,"Borderline","At risk")) -> Safe | L30: =RANK(H30,$H$22:$H$31)+COUNTIF($H$22:H30,H30)-1 -> 4 | M30: =IF(E30=1,"Back-to-back weeks",IF(E30>=4,"Long gap","")) | N30: =IF(E30>=2,H30,-1) -> 68.832884 | O30: =1-NORMDIST(Assumptions!$B$13,H30,Assumptions!$B$33,1) -> 0.8873066 | P30: =NORMINV(0.1,H30,Assumptions!$B$34) -> 49.299415 | Q30: =A30&"+"&B30 -> GAGWI+GADOU
A31: GAALB | B31: GADOU | C31: =INDEX($C$14:$C$18,MATCH(A31,$A$14:$A$18,0)) -> 4 | D31: =INDEX($C$14:$C$18,MATCH(B31,$A$14:$A$18,0)) -> 5 | E31: =ABS(D31-C31) -> 1 | F31: =INDEX($G$14:$G$18,MATCH(A31,$A$14:$A$18,0)) -> 34.016897 | G31: =INDEX($G$14:$G$18,MATCH(B31,$A$14:$A$18,0)) -> 38.384932 | H31: =F31+G31 -> 72.401829 | I31: =2*(INDEX($D$14:$D$18,MATCH(A31,$A$14:$A$18,0))+INDEX($D$14:$D$18,MATCH(B31,$A$14:$A$18,0))) -> 16.539736 | J31: =H31-Assumptions!$B$13 -> 22.401829 | K31: =IF(H31>=Assumptions!$B$14,"Safe",IF(H31>=Assumptions!$B$13,"Borderline","At risk")) -> Safe | L31: =RANK(H31,$H$22:$H$31)+COUNTIF($H$22:H31,H31)-1 -> 1 | M31: =IF(E31=1,"Back-to-back weeks",IF(E31>=4,"Long gap","")) -> Back-to-back weeks | N31: =IF(E31>=2,H31,-1) -> -1 | O31: =1-NORMDIST(Assumptions!$B$13,H31,Assumptions!$B$33,1) -> 0.92535891 | P31: =NORMINV(0.1,H31,Assumptions!$B$34) -> 52.868359 | Q31: =A31&"+"&B31 -> GAALB+GADOU
A33: Best by expected points | B33: =INDEX($A$22:$A$31,MATCH(1,$L$22:$L$31,0))&" + "&INDEX($B$22:$B$31,MATCH(1,$L$22:$L$31,0)) -> GAALB + GADOU | C33: =INDEX($H$22:$H$31,MATCH(1,$L$22:$L$31,0)) -> 72.401829
A34: Least driving | B34: =INDEX($A$22:$A$31,MATCH(MIN($I$22:$I$31),$I$22:$I$31,0))&" + "&INDEX($B$22:$B$31,MATCH(MIN($I$22:$I$31),$I$22:$I$31,0)) -> GAGWI + GAALB | C34: =INDEX($H$22:$H$31,MATCH(MIN($I$22:$I$31),$I$22:$I$31,0)) -> 64.464849
A35: Best with ≥ 2-week gap | B35: =INDEX($A$22:$A$31,MATCH(MAX($N$22:$N$31),$N$22:$N$31,0))&" + "&INDEX($B$22:$B$31,MATCH(MAX($N$22:$N$31),$N$22:$N$31,0)) -> GAGAI + GADOU | C35: =MAX($N$22:$N$31) -> 70.536132
A37: Registration outcomes: what each lottery result means
A38: Outcome (Round 1 / Round 2) | B38: Events | C38: Expected pre-DCMP pts | D38: Chance of making cut | E38: Bad-luck total (1 in 10)
A39: First choice / first choice | B39: Albany + Gainesville | C39: =INDEX($H$22:$H$31,MATCH("GAGAI+GAALB",$Q$22:$Q$31,0)) -> 66.168097 | D39: =INDEX($O$22:$O$31,MATCH("GAGAI+GAALB",$Q$22:$Q$31,0)) -> 0.85101301 | E39: =INDEX($P$22:$P$31,MATCH("GAGAI+GAALB",$Q$22:$Q$31,0)) -> 46.634628
A40: First choice / second choice | B40: Albany + Dalton | C40: =INDEX($H$22:$H$31,MATCH("GADAL+GAALB",$Q$22:$Q$31,0)) -> 64.464849 | D40: =INDEX($O$22:$O$31,MATCH("GADAL+GAALB",$Q$22:$Q$31,0)) -> 0.82411068 | E40: =INDEX($P$22:$P$31,MATCH("GADAL+GAALB",$Q$22:$Q$31,0)) -> 44.93138
A41: Second choice / first choice | B41: Dalton + Albany | C41: =INDEX($H$22:$H$31,MATCH("GADAL+GAALB",$Q$22:$Q$31,0)) -> 64.464849 | D41: =INDEX($O$22:$O$31,MATCH("GADAL+GAALB",$Q$22:$Q$31,0)) -> 0.82411068 | E41: =INDEX($P$22:$P$31,MATCH("GADAL+GAALB",$Q$22:$Q$31,0)) -> 44.93138
A42: Second choice / second choice | B42: Dalton + Gwinnett | C42: =INDEX($H$22:$H$31,MATCH("GADAL+GAGWI",$Q$22:$Q$31,0)) -> 60.895905 | D42: =INDEX($O$22:$O$31,MATCH("GADAL+GAGWI",$Q$22:$Q$31,0)) -> 0.75847373 | E42: =INDEX($P$22:$P$31,MATCH("GADAL+GAGWI",$Q$22:$Q$31,0)) -> 41.362435
A43: Second choice in both rounds (Dalton W1 + Gwinnett W3): about 5 fewer expected points than the target, the toughest forecast field (Dalton), the least build time (Week 1) and the most driving, but the most rebuild time (12 days) and Macon prep (16 days).
A45: How to read: k counts forecast attendees with a higher 2026 blended strength than the focus team. Fewer stronger teams → better qualification seed, captain/early-pick odds and playoff depth, which is where most district points come from.
A46: Sanity check: the same formula gives 3329 about 66 points for its actual 2026 fields (k = 10 at Dalton, 9 at Columbus) vs 64 earned.
...

Sheet Events 2027
A1: 2027 PCH events — forecast attendance and competitive density
A2: Competitive index = 3 × top-10 teams + 2 × top-11–25 + 1 × top-26–45 (by 2026 blended strength). All counts are live formulas on Forecast 2027.
A4: Code | B4: Event | C4: Week | D4: Dates | E4: City | F4: Capacity | G4: Forecast teams | H4: Fill % | I4: Top-10 teams | J4: Top 11–25 | K4: Top 26–45 | L4: Avg strength | M4: Competitive index | N4: Density rank (1 = toughest)
A5: GADAL | B5: PCH District Dalton Event presented by Shaw Industries | C5: 1 | D5: Mar 4–6, 2027 | E5: Dalton | F5: 30 | G5: =COUNTIF('Forecast 2027'!$F$2:$F$75,A5)+COUNTIF('Forecast 2027'!$G$2:$G$75,A5) -> 30 | H5: =G5/F5 -> 1 | I5: =SUMPRODUCT(('Forecast 2027'!$F$2:$F$75=A5)*('Forecast 2027'!$E$2:$E$75>=1)*('Forecast 2027'!$E$2:$E$75<=10))+SUMPRODUCT(('Forecast 2027'!$G$2:$G$75=A5)*('Forecast 2027'!$E$2:$E$75>=1)*('Forecast 2027'!$E$2:$E$75<=10)) -> 5 | J5: =SUMPRODUCT(('Forecast 2027'!$F$2:$F$75=A5)*('Forecast 2027'!$E$2:$E$75>=11)*('Forecast 2027'!$E$2:$E$75<=25))+SUMPRODUCT(('Forecast 2027'!$G$2:$G$75=A5)*('Forecast 2027'!$E$2:$E$75>=11)*('Forecast 2027'!$E$2:$E$75<=25)) -> 6 | K5: =SUMPRODUCT(('Forecast 2027'!$F$2:$F$75=A5)*('Forecast 2027'!$E$2:$E$75>=26)*('Forecast 2027'!$E$2:$E$75<=45))+SUMPRODUCT(('Forecast 2027'!$G$2:$G$75=A5)*('Forecast 2027'!$E$2:$E$75>=26)*('Forecast 2027'!$E$2:$E$75<=45)) -> 12 | L5: =IF(ISERROR((SUMIF('Forecast 2027'!$F$2:$F$75,A5,'Forecast 2027'!$D$2:$D$75)+SUMIF('Forecast 2027'!$G$2:$G$75,A5,'Forecast 2027'!$D$2:$D$75))/G5),0,(SUMIF('Forecast 2027'!$F$2:$F$75,A5,'Forecast 2027'!$D$2:$D$75)+SUMIF('Forecast 2027'!$G$2:$G$75,A5,'Forecast 2027'!$D$2:$D$75))/G5) -> 40.305519 | M5: =3*I5+2*J5+K5 -> 39 | N5: =RANK(M5,$M$5:$M$9) -> 1
A6: GAGAI | B6: PCH District Gainesville Event presented by Honeywell Tech | C6: 2 | D6: Mar 11–13, 2027 | E6: Gainesville | F6: 30 | G6: =COUNTIF('Forecast 2027'!$F$2:$F$75,A6)+COUNTIF('Forecast 2027'!$G$2:$G$75,A6) -> 30 | H6: =G6/F6 -> 1 | I6: =SUMPRODUCT(('Forecast 2027'!$F$2:$F$75=A6)*('Forecast 2027'!$E$2:$E$75>=1)*('Forecast 2027'!$E$2:$E$75<=10))+SUMPRODUCT(('Forecast 2027'!$G$2:$G$75=A6)*('Forecast 2027'!$E$2:$E$75>=1)*('Forecast 2027'!$E$2:$E$75<=10)) -> 3 | J6: =SUMPRODUCT(('Forecast 2027'!$F$2:$F$75=A6)*('Forecast 2027'!$E$2:$E$75>=11)*('Forecast 2027'!$E$2:$E$75<=25))+SUMPRODUCT(('Forecast 2027'!$G$2:$G$75=A6)*('Forecast 2027'!$E$2:$E$75>=11)*('Forecast 2027'!$E$2:$E$75<=25)) -> 7 | K6: =SUMPRODUCT(('Forecast 2027'!$F$2:$F$75=A6)*('Forecast 2027'!$E$2:$E$75>=26)*('Forecast 2027'!$E$2:$E$75<=45))+SUMPRODUCT(('Forecast 2027'!$G$2:$G$75=A6)*('Forecast 2027'!$E$2:$E$75>=26)*('Forecast 2027'!$E$2:$E$75<=45)) -> 7 | L6: =IF(ISERROR((SUMIF('Forecast 2027'!$F$2:$F$75,A6,'Forecast 2027'!$D$2:$D$75)+SUMIF('Forecast 2027'!$G$2:$G$75,A6,'Forecast 2027'!$D$2:$D$75))/G6),0,(SUMIF('Forecast 2027'!$F$2:$F$75,A6,'Forecast 2027'!$D$2:$D$75)+SUMIF('Forecast 2027'!$G$2:$G$75,A6,'Forecast 2027'!$D$2:$D$75))/G6) -> 33.933515 | M6: =3*I6+2*J6+K6 -> 30 | N6: =RANK(M6,$M$5:$M$9) -> 4
A7: GAGWI | B7: PCH District Gwinnett Event presented by Zebra Technologies | C7: 3 | D7: Mar 19–21, 2027 | E7: Lawrenceville | F7: 30 | G7: =COUNTIF('Forecast 2027'!$F$2:$F$75,A7)+COUNTIF('Forecast 2027'!$G$2:$G$75,A7) -> 30 | H7: =G7/F7 -> 1 | I7: =SUMPRODUCT(('Forecast 2027'!$F$2:$F$75=A7)*('Forecast 2027'!$E$2:$E$75>=1)*('Forecast 2027'!$E$2:$E$75<=10))+SUMPRODUCT(('Forecast 2027'!$G$2:$G$75=A7)*('Forecast 2027'!$E$2:$E$75>=1)*('Forecast 2027'!$E$2:$E$75<=10)) -> 4 | J7: =SUMPRODUCT(('Forecast 2027'!$F$2:$F$75=A7)*('Forecast 2027'!$E$2:$E$75>=11)*('Forecast 2027'!$E$2:$E$75<=25))+SUMPRODUCT(('Forecast 2027'!$G$2:$G$75=A7)*('Forecast 2027'!$E$2:$E$75>=11)*('Forecast 2027'!$E$2:$E$75<=25)) -> 7 | K7: =SUMPRODUCT(('Forecast 2027'!$F$2:$F$75=A7)*('Forecast 2027'!$E$2:$E$75>=26)*('Forecast 2027'!$E$2:$E$75<=45))+SUMPRODUCT(('Forecast 2027'!$G$2:$G$75=A7)*('Forecast 2027'!$E$2:$E$75>=26)*('Forecast 2027'!$E$2:$E$75<=45)) -> 6 | L7: =IF(ISERROR((SUMIF('Forecast 2027'!$F$2:$F$75,A7,'Forecast 2027'!$D$2:$D$75)+SUMIF('Forecast 2027'!$G$2:$G$75,A7,'Forecast 2027'!$D$2:$D$75))/G7),0,(SUMIF('Forecast 2027'!$F$2:$F$75,A7,'Forecast 2027'!$D$2:$D$75)+SUMIF('Forecast 2027'!$G$2:$G$75,A7,'Forecast 2027'!$D$2:$D$75))/G7) -> 36.528104 | M7: =3*I7+2*J7+K7 -> 32 | N7: =RANK(M7,$M$5:$M$9) -> 2
A8: GAALB | B8: PCH District Albany Event presented by Procter & Gamble | C8: 4 | D8: Mar 25–27, 2027 | E8: Albany | F8: 29 | G8: =COUNTIF('Forecast 2027'!$F$2:$F$75,A8)+COUNTIF('Forecast 2027'!$G$2:$G$75,A8) -> 28 | H8: =G8/F8 -> 0.96551724 | I8: =SUMPRODUCT(('Forecast 2027'!$F$2:$F$75=A8)*('Forecast 2027'!$E$2:$E$75>=1)*('Forecast 2027'!$E$2:$E$75<=10))+SUMPRODUCT(('Forecast 2027'!$G$2:$G$75=A8)*('Forecast 2027'!$E$2:$E$75>=1)*('Forecast 2027'!$E$2:$E$75<=10)) -> 5 | J8: =SUMPRODUCT(('Forecast 2027'!$F$2:$F$75=A8)*('Forecast 2027'!$E$2:$E$75>=11)*('Forecast 2027'!$E$2:$E$75<=25))+SUMPRODUCT(('Forecast 2027'!$G$2:$G$75=A8)*('Forecast 2027'!$E$2:$E$75>=11)*('Forecast 2027'!$E$2:$E$75<=25)) -> 5 | K8: =SUMPRODUCT(('Forecast 2027'!$F$2:$F$75=A8)*('Forecast 2027'!$E$2:$E$75>=26)*('Forecast 2027'!$E$2:$E$75<=45))+SUMPRODUCT(('Forecast 2027'!$G$2:$G$75=A8)*('Forecast 2027'!$E$2:$E$75>=26)*('Forecast 2027'!$E$2:$E$75<=45)) -> 7 | L8: =IF(ISERROR((SUMIF('Forecast 2027'!$F$2:$F$75,A8,'Forecast 2027'!$D$2:$D$75)+SUMIF('Forecast 2027'!$G$2:$G$75,A8,'Forecast 2027'!$D$2:$D$75))/G8),0,(SUMIF('Forecast 2027'!$F$2:$F$75,A8,'Forecast 2027'!$D$2:$D$75)+SUMIF('Forecast 2027'!$G$2:$G$75,A8,'Forecast 2027'!$D$2:$D$75))/G8) -> 40.482294 | M8: =3*I8+2*J8+K8 -> 32 | N8: =RANK(M8,$M$5:$M$9) -> 2
A9: GADOU | B9: PCH District Douglasville Event (new for 2027) | C9: 5 | D9: Apr 1–3, 2027 | E9: Douglasville | F9: 30 | G9: =COUNTIF('Forecast 2027'!$F$2:$F$75,A9)+COUNTIF('Forecast 2027'!$G$2:$G$75,A9) -> 30 | H9: =G9/F9 -> 1 | I9: =SUMPRODUCT(('Forecast 2027'!$F$2:$F$75=A9)*('Forecast 2027'!$E$2:$E$75>=1)*('Forecast 2027'!$E$2:$E$75<=10))+SUMPRODUCT(('Forecast 2027'!$G$2:$G$75=A9)*('Forecast 2027'!$E$2:$E$75>=1)*('Forecast 2027'!$E$2:$E$75<=10)) -> 3 | J9: =SUMPRODUCT(('Forecast 2027'!$F$2:$F$75=A9)*('Forecast 2027'!$E$2:$E$75>=11)*('Forecast 2027'!$E$2:$E$75<=25))+SUMPRODUCT(('Forecast 2027'!$G$2:$G$75=A9)*('Forecast 2027'!$E$2:$E$75>=11)*('Forecast 2027'!$E$2:$E$75<=25)) -> 5 | K9: =SUMPRODUCT(('Forecast 2027'!$F$2:$F$75=A9)*('Forecast 2027'!$E$2:$E$75>=26)*('Forecast 2027'!$E$2:$E$75<=45))+SUMPRODUCT(('Forecast 2027'!$G$2:$G$75=A9)*('Forecast 2027'!$E$2:$E$75>=26)*('Forecast 2027'!$E$2:$E$75<=45)) -> 8 | L9: =IF(ISERROR((SUMIF('Forecast 2027'!$F$2:$F$75,A9,'Forecast 2027'!$D$2:$D$75)+SUMIF('Forecast 2027'!$G$2:$G$75,A9,'Forecast 2027'!$D$2:$D$75))/G9),0,(SUMIF('Forecast 2027'!$F$2:$F$75,A9,'Forecast 2027'!$D$2:$D$75)+SUMIF('Forecast 2027'!$G$2:$G$75,A9,'Forecast 2027'!$D$2:$D$75))/G9) -> 31.71262 | M9: =3*I9+2*J9+K9 -> 27 | N9: =RANK(M9,$M$5:$M$9) -> 5
A10: Total | F10: =SUM(F5:F9) -> 149 | G10: =SUM(G5:G9) -> 148
A11: GACMP | B11: Peachtree District Championship presented by Mercer University | C11: 6 | D11: Apr 7–9, 2027 | E11: Macon | G11: Top 45 by district points (2026 precedent)
A14: 2026 actual (same method, using Results 2026)
A15: Code | B15: City | C15: Week | D15: Dates | G15: Teams | I15: Top-10 teams | J15: Top 11–25 | K15: Top 26–45 | L15: Avg strength | M15: Competitive index | N15: Density rank
A16: GADAL | B16: Dalton | C16: 1 | D16: Mar 5–7, 2026 | G16: =COUNTIF('Results 2026'!$A$2:$A$149,A16) -> 31 | I16: =SUMPRODUCT(('Results 2026'!$A$2:$A$149=A16)*('Results 2026'!$H$2:$H$149>=1)*('Results 2026'!$H$2:$H$149<=10)) -> 5 | J16: =SUMPRODUCT(('Results 2026'!$A$2:$A$149=A16)*('Results 2026'!$H$2:$H$149>=11)*('Results 2026'!$H$2:$H$149<=25)) -> 5 | K16: =SUMPRODUCT(('Results 2026'!$A$2:$A$149=A16)*('Results 2026'!$H$2:$H$149>=26)*('Results 2026'!$H$2:$H$149<=45)) -> 12 | L16: =IF(ISERROR(SUMIF('Results 2026'!$A$2:$A$149,A16,'Results 2026'!$I$2:$I$149)/G16),0,SUMIF('Results 2026'!$A$2:$A$149,A16,'Results 2026'!$I$2:$I$149)/G16) -> 37.900528 | M16: =3*I16+2*J16+K16 -> 37 | N16: =RANK(M16,$M$16:$M$20) -> 1
A17: GAGWI | B17: Lawrenceville | C17: 2 | D17: Mar 13–15, 2026 | G17: =COUNTIF('Results 2026'!$A$2:$A$149,A17) -> 30 | I17: =SUMPRODUCT(('Results 2026'!$A$2:$A$149=A17)*('Results 2026'!$H$2:$H$149>=1)*('Results 2026'!$H$2:$H$149<=10)) -> 4 | J17: =SUMPRODUCT(('Results 2026'!$A$2:$A$149=A17)*('Results 2026'!$H$2:$H$149>=11)*('Results 2026'!$H$2:$H$149<=25)) -> 7 | K17: =SUMPRODUCT(('Results 2026'!$A$2:$A$149=A17)*('Results 2026'!$H$2:$H$149>=26)*('Results 2026'!$H$2:$H$149<=45)) -> 6 | L17: =IF(ISERROR(SUMIF('Results 2026'!$A$2:$A$149,A17,'Results 2026'!$I$2:$I$149)/G17),0,SUMIF('Results 2026'!$A$2:$A$149,A17,'Results 2026'!$I$2:$I$149)/G17) -> 36.826139 | M17: =3*I17+2*J17+K17 -> 32 | N17: =RANK(M17,$M$16:$M$20) -> 2
A18: GACOL | B18: Columbus | C18: 3 | D18: Mar 19–21, 2026 | G18: =COUNTIF('Results 2026'!$A$2:$A$149,A18) -> 29 | I18: =SUMPRODUCT(('Results 2026'!$A$2:$A$149=A18)*('Results 2026'!$H$2:$H$149>=1)*('Results 2026'!$H$2:$H$149<=10)) -> 4 | J18: =SUMPRODUCT(('Results 2026'!$A$2:$A$149=A18)*('Results 2026'!$H$2:$H$149>=11)*('Results 2026'!$H$2:$H$149<=25)) -> 6 | K18: =SUMPRODUCT(('Results 2026'!$A$2:$A$149=A18)*('Results 2026'!$H$2:$H$149>=26)*('Results 2026'!$H$2:$H$149<=45)) -> 7 | L18: =IF(ISERROR(SUMIF('Results 2026'!$A$2:$A$149,A18,'Results 2026'!$I$2:$I$149)/G18),0,SUMIF('Results 2026'!$A$2:$A$149,A18,'Results 2026'!$I$2:$I$149)/G18) -> 35.371255 | M18: =3*I18+2*J18+K18 -> 31 | N18: =RANK(M18,$M$16:$M$20) -> 3
A19: GAALB | B19: Albany | C19: 4 | D19: Mar 26–28, 2026 | G19: =COUNTIF('Results 2026'!$A$2:$A$149,A19) -> 28 | I19: =SUMPRODUCT(('Results 2026'!$A$2:$A$149=A19)*('Results 2026'!$H$2:$H$149>=1)*('Results 2026'!$H$2:$H$149<=10)) -> 4 | J19: =SUMPRODUCT(('Results 2026'!$A$2:$A$149=A19)*('Results 2026'!$H$2:$H$149>=11)*('Results 2026'!$H$2:$H$149<=25)) -> 6 | K19: =SUMPRODUCT(('Results 2026'!$A$2:$A$149=A19)*('Results 2026'!$H$2:$H$149>=26)*('Results 2026'!$H$2:$H$149<=45)) -> 7 | L19: =IF(ISERROR(SUMIF('Results 2026'!$A$2:$A$149,A19,'Results 2026'!$I$2:$I$149)/G19),0,SUMIF('Results 2026'!$A$2:$A$149,A19,'Results 2026'!$I$2:$I$149)/G19) -> 39.286422 | M19: =3*I19+2*J19+K19 -> 31 | N19: =RANK(M19,$M$16:$M$20) -> 3
A20: GAGAI | B20: Gainesville | C20: 5 | D20: Apr 2–4, 2026 | G20: =COUNTIF('Results 2026'!$A$2:$A$149,A20) -> 30 | I20: =SUMPRODUCT(('Results 2026'!$A$2:$A$149=A20)*('Results 2026'!$H$2:$H$149>=1)*('Results 2026'!$H$2:$H$149<=10)) -> 3 | J20: =SUMPRODUCT(('Results 2026'!$A$2:$A$149=A20)*('Results 2026'!$H$2:$H$149>=11)*('Results 2026'!$H$2:$H$149<=25)) -> 6 | K20: =SUMPRODUCT(('Results 2026'!$A$2:$A$149=A20)*('Results 2026'!$H$2:$H$149>=26)*('Results 2026'!$H$2:$H$149<=45)) -> 8 | L20: =IF(ISERROR(SUMIF('Results 2026'!$A$2:$A$149,A20,'Results 2026'!$I$2:$I$149)/G20),0,SUMIF('Results 2026'!$A$2:$A$149,A20,'Results 2026'!$I$2:$I$149)/G20) -> 33.413674 | M20: =3*I20+2*J20+K20 -> 29 | N20: =RANK(M20,$M$16:$M$20) -> 5
A22: Source: 2027 dates, weeks and capacities from FIRST FRC Events 2027 Season Event List (rendered 9/22/2026). Capacities exclude any reserve slots.

Sheet Forecast 2027
A1: Team | B1: Name | C1: City | D1: Strength | E1: Strength rank | F1: Event A | G1: Event B | H1: Week A | I1: Week B | J1: Gap (wks) | K1: Drive A (h) | L1: Drive B (h) | M1: 2026 events | N1: Venues kept from 2026 | O1: Confidence | P1: Rationale | Q1: Next-best pair | S1: Focus team | T1: =Assumptions!B20 -> 3329
A2: 1833 | B2: =INDEX(Strength!$B$2:$B$76,MATCH(A2,Strength!$A$2:$A$76,0)) -> Team BEAN | C2: =INDEX(Strength!$C$2:$C$76,MATCH(A2,Strength!$A$2:$A$76,0)) -> Cumming | D2: =INDEX(Strength!$U$2:$U$76,MATCH(A2,Strength!$A$2:$A$76,0)) -> 100 | E2: =INDEX(Strength!$V$2:$V$76,MATCH(A2,Strength!$A$2:$A$76,0)) -> 1 | F2: GAGAI | G2: GAGWI | H2: =IF(ISERROR(INDEX('Events 2027'!$C$5:$C$9,MATCH(F2,'Events 2027'!$A$5:$A$9,0))),"",INDEX('Events 2027'!$C$5:$C$9,MATCH(F2,'Events 2027'!$A$5:$A$9,0))) -> 2 | I2: =IF(ISERROR(INDEX('Events 2027'!$C$5:$C$9,MATCH(G2,'Events 2027'!$A$5:$A$9,0))),"",INDEX('Events 2027'!$C$5:$C$9,MATCH(G2,'Events 2027'!$A$5:$A$9,0))) -> 3 | J2: =IF(ISERROR(ABS(I2-H2)),"",ABS(I2-H2)) -> 1 | K2: =IF(ISERROR(INDEX('Drive Times'!$D$12:$I$51,MATCH(C2,'Drive Times'!$A$12:$A$51,0),MATCH(F2,'Drive Times'!$D$11:$I$11,0))),"",INDEX('Drive Times'!$D$12:$I$51,MATCH(C2,'Drive Times'!$A$12:$A$51,0),MATCH(F2,'Drive Times'!$D$11:$I$11,0))) -> 0.57760322 | L2: =IF(ISERROR(INDEX('Drive Times'!$D$12:$I$51,MATCH(C2,'Drive Times'!$A$12:$A$51,0),MATCH(G2,'Drive Times'!$D$11:$I$11,0))),"",INDEX('Drive Times'!$D$12:$I$51,MATCH(C2,'Drive Times'!$A$12:$A$51,0),MATCH(G2,'Drive Times'!$D$11:$I$11,0))) -> 0.58293458 | M2: Gwinnett + Gainesville | N2: 2 | O2: High | P2: Gainesville: returning venue (0.6 h); Lawrenceville: returning venue (0.6 h) | Q2: GAGAI + GADOU
A3: 4188 | B3: =INDEX(Strength!$B$2:$B$76,MATCH(A3,Strength!$A$2:$A$76,0)) -> Columbus Space Program | C3: =INDEX(Strength!$C$2:$C$76,MATCH(A3,Strength!$A$2:$A$76,0)) -> Columbus | D3: =INDEX(Strength!$U$2:$U$76,MATCH(A3,Strength!$A$2:$A$76,0)) -> 93.195971 | E3: =INDEX(Strength!$V$2:$V$76,MATCH(A3,Strength!$A$2:$A$76,0)) -> 2 | F3: GAALB | G3: GADOU | H3: =IF(ISERROR(INDEX('Events 2027'!$C$5:$C$9,MATCH(F3,'Events 2027'!$A$5:$A$9,0))),"",INDEX('Events 2027'!$C$5:$C$9,MATCH(F3,'Events 2027'!$A$5:$A$9,0))) -> 4 | I3: =IF(ISERROR(INDEX('Events 2027'!$C$5:$C$9,MATCH(G3,'Events 2027'!$A$5:$A$9,0))),"",INDEX('Events 2027'!$C$5:$C$9,MATCH(G3,'Events 2027'!$A$5:$A$9,0))) -> 5 | J3: =IF(ISERROR(ABS(I3-H3)),"",ABS(I3-H3)) -> 1 | K3: =IF(ISERROR(INDEX('Drive Times'!$D$12:$I$51,MATCH(C3,'Drive Times'!$A$12:$A$51,0),MATCH(F3,'Drive Times'!$D$11:$I$11,0))),"",INDEX('Drive Times'!$D$12:$I$51,MATCH(C3,'Drive Times'!$A$12:$A$51,0),MATCH(F3,'Drive Times'!$D$11:$I$11,0))) -> 1.6586581 | L3: =IF(ISERROR(INDEX('Drive Times'!$D$12:$I$51,MATCH(C3,'Drive Times'!$A$12:$A$51,0),MATCH(G3,'Drive Times'!$D$11:$I$11,0))),"",INDEX('Drive Times'!$D$12:$I$51,MATCH(C3,'Drive Times'!$A$12:$A$51,0),MATCH(G3,'Drive Times'!$D$11:$I$11,0))) -> 1.8809611 | M3: Columbus + Albany | N3: 1 | O3: Low | P3: Albany: returning venue (1.7 h); Douglasville: closest open option (1.9 h); Columbus retired for 2027; moved by capacity from Gainesville/Albany | Q3: GAGAI + GAALB
A4: 1002 | B4: =INDEX(Strength!$B$2:$B$76,MATCH(A4,Strength!$A$2:$A$76,0)) -> CircuitRunners Robotics | C4: =INDEX(Strength!$C$2:$C$76,MATCH(A4,Strength!$A$2:$A$76,0)) -> Marietta | D4: =INDEX(Strength!$U$2:$U$76,MATCH(A4,Strength!$A$2:$A$76,0)) -> 93.014811 | E4: =INDEX(Strength!$V$2:$V$76,MATCH(A4,Strength!$A$2:$A$76,0)) -> 3 | F4: GADAL | G4: GAALB | H4: =IF(ISERROR(INDEX('Events 2027'!$C$5:$C$9,MATCH(F4,'Events 2027'!$A$5:$A$9,0))),"",INDEX('Events 2027'!$C$5:$C$9,MATCH(F4,'Events 2027'!$A$5:$A$9,0))) -> 1 | I4: =IF(ISERROR(INDEX('Events 2027'!$C$5:$C$9,MATCH(G4,'Events 2027'!$A$5:$A$9,0))),"",INDEX('Events 2027'!$C$5:$C$9,MATCH(G4,'Events 2027'!$A$5:$A$9,0))) -> 4 | J4: =IF(ISERROR(ABS(I4-H4)),"",ABS(I4-H4)) -> 3 | K4: =IF(ISERROR(INDEX('Drive Times'!$D$12:$I$51,MATCH(C4,'Drive Times'!$A$12:$A$51,0),MATCH(F4,'Drive Times'!$D$11:$I$11,0))),"",INDEX('Drive Times'!$D$12:$I$51,MATCH(C4,'Drive Times'!$A$12:$A$51,0),MATCH(F4,'Drive Times'!$D$11:$I$11,0))) -> 1.351338 | L4: =IF(ISERROR(INDEX('Drive Times'!$D$12:$I$51,MATCH(C4,'Drive Times'!$A$12:$A$51,0),MATCH(G4,'Drive Times'!$D$11:$I$11,0))),"",INDEX('Drive Times'!$D$12:$I$51,MATCH(C4,'Drive Times'!$A$12:$A$51,0),MATCH(G4,'Drive Times'!$D$11:$I$11,0))) -> 3.264342 | M4: Dalton + Albany | N4: 2 | O4: Medium | P4: Dalton: returning venue (1.4 h); Albany: returning venue (3.3 h) | Q4: GADAL + GAGWI
A5: 6919 | B5: =INDEX(Strength!$B$2:$B$76,MATCH(A5,Strength!$A$2:$A$76,0)) -> The Commodores | C5: =INDEX(Strength!$C$2:$C$76,MATCH(A5,Strength!$A$2:$A$76,0)) -> Albany | D5: =INDEX(Strength!$U$2:$U$76,MATCH(A5,Strength!$A$2:$A$76,0)) -> 86.620879 | E5: =INDEX(Strength!$V$2:$V$76,MATCH(A5,Strength!$A$2:$A$76,0)) -> 4 | F5: GADAL | G5: GAALB | H5: =IF(ISERROR(INDEX('Events 2027'!$C$5:$C$9,MATCH(F5,'Events 2027'!$A$5:$A$9,0))),"",INDEX('Events 2027'!$C$5:$C$9,MATCH(F5,'Events 2027'!$A$5:$A$9,0))) -> 1 | I5: =IF(ISERROR(INDEX('Events 2027'!$C$5:$C$9,MATCH(G5,'Events 2027'!$A$5:$A$9,0))),"",INDEX('Events 2027'!$C$5:$C$9,MATCH(G5,'Events 2027'!$A$5:$A$9,0))) -> 4 | J5: =IF(ISERROR(ABS(I5-H5)),"",ABS(I5-H5)) -> 3 | K5: =IF(ISERROR(INDEX('Drive Times'!$D$12:$I$51,MATCH(C5,'Drive Times'!$A$12:$A$51,0),MATCH(F5,'Drive Times'!$D$11:$I$11,0))),"",INDEX('Drive Times'!$D$12:$I$51,MATCH(C5,'Drive Times'!$A$12:$A$51,0),MATCH(F5,'Drive Times'!$D$11:$I$11,0))) -> 4.3609642 | L5: =IF(ISERROR(INDEX('Drive Times'!$D$12:$I$51,MATCH(C5,'Drive Times'!$A$12:$A$51,0),MATCH(G5,'Drive Times'!$D$11:$I$11,0))),"",INDEX('Drive Times'!$D$12:$I$51,MATCH(C5,'Drive Times'!$A$12:$A$51,0),MATCH(G5,'Drive Times'!$D$11:$I$11,0))) -> 0 | M5: Dalton + Albany | N5: 2 | O5: High | P5: Dalton: returning venue (4.4 h); Albany: returning venue (0.0 h) | Q5: GAGAI + GAALB
A6: 1771 | B6: =INDEX(Strength!$B$2:$B$76,MATCH(A6,Strength!$A$2:$A$76,0)) -> North Gwinnett Robotics | C6: =INDEX(Strength!$C$2:$C$76,MATCH(A6,Strength!$A$2:$A$76,0)) -> Suwanee | D6: =INDEX(Strength!$U$2:$U$76,MATCH(A6,Strength!$A$2:$A$76,0)) -> 84.194139 | E6: =INDEX(Strength!$V$2:$V$76,MATCH(A6,Strength!$A$2:$A$76,0)) -> 5 | F6: GAGWI | G6: GAALB | H6: =IF(ISERROR(INDEX('Events 2027'!$C$5:$C$9,MATCH(F6,'Events 2027'!$A$5:$A$9,0))),"",INDEX('Events 2027'!$C$5:$C$9,MATCH(F6,'Events 2027'!$A$5:$A$9,0))) -> 3 | I6: =IF(ISERROR(INDEX('Events 2027'!$C$5:$C$9,MATCH(G6,'Events 2027'!$A$5:$A$9,0))),"",INDEX('Events 2027'!$C$5:$C$9,MATCH(G6,'Events 2027'!$A$5:$A$9,0))) -> 4 | J6: =IF(ISERROR(ABS(I6-H6)),"",ABS(I6-H6)) -> 1 | K6: =IF(ISERROR(INDEX('Drive Times'!$D$12:$I$51,MATCH(C6,'Drive Times'!$A$12:$A$51,0),MATCH(F6,'Drive Times'!$D$11:$I$11,0))),"",INDEX('Drive Times'!$D$12:$I$51,MATCH(C6,'Drive Times'!$A$12:$A$51,0),MATCH(F6,'Drive Times'!$D$11:$I$11,0))) -> 0.37586064 | L6: =IF(ISERROR(INDEX('Drive Times'!$D$12:$I$51,MATCH(C6,'Drive Times'!$A$12:$A$51,0),MATCH(G6,'Drive Times'!$D$11:$I$11,0))),"",INDEX('Drive Times'!$D$12:$I$51,MATCH(C6,'Drive Times'!$A$12:$A$51,0),MATCH(G6,'Drive Times'!$D$11:$I$11,0))) -> 3.3606475 | M6: Gwinnett + Albany | N6: 2 | O6: High | P6: Lawrenceville: returning venue (0.4 h); Albany: returning venue (3.4 h) | Q6: GAGWI + GADOU
A7: 2974 | B7: =INDEX(Strength!$B$2:$B$76,MATCH(A7,Strength!$A$2:$A$76,0)) -> Walton Robotics | C7: =INDEX(Strength!$C$2:$C$76,MATCH(A7,Strength!$A$2:$A$76,0)) -> Marietta | D7: =INDEX(Strength!$U$2:$U$76,MATCH(A7,Strength!$A$2:$A$76,0)) -> 82.097468 | E7: =INDEX(Strength!$V$2:$V$76,MATCH(A7,Strength!$A$2:$A$76,0)) -> 6 | F7: GADAL | G7: GADOU | H7: =IF(ISERROR(INDEX('Events 2027'!$C$5:$C$9,MATCH(F7,'Events 2027'!$A$5:$A$9,0))),"",INDEX('Events 2027'!$C$5:$C$9,MATCH(F7,'Events 2027'!$A$5:$A$9,0))) -> 1 | I7: =IF(ISERROR(INDEX('Events 2027'!$C$5:$C$9,MATCH(G7,'Events 2027'!$A$5:$A$9,0))),"",INDEX('Events 2027'!$C$5:$C$9,MATCH(G7,'Events 2027'!$A$5:$A$9,0))) -> 5 | J7: =IF(ISERROR(ABS(I7-H7)),"",ABS(I7-H7)) -> 4 | K7: =IF(ISERROR(INDEX('Drive Times'!$D$12:$I$51,MATCH(C7,'Drive Times'!$A$12:$A$51,0),MATCH(F7,'Drive Times'!$D$11:$I$11,0))),"",INDEX('Drive Times'!$D$12:$I$51,MATCH(C7,'Drive Times'!$A$12:$A$51,0),MATCH(F7,'Drive Times'!$D$11:$I$11,0))) -> 1.351338 | L7: =IF(ISERROR(INDEX('Drive Times'!$D$12:$I$51,MATCH(C7,'Drive Times'!$A$12:$A$51,0),MATCH(G7,'Drive Times'!$D$11:$I$11,0))),"",INDEX('Drive Times'!$D$12:$I$51,MATCH(C7,'Drive Times'!$A$12:$A$51,0),MATCH(G7,'Drive Times'!$D$11:$I$11,0))) -> 0.55651636 | M7: Dalton + Columbus | N7: 1 | O7: Low | P7: Dalton: returning venue (1.4 h); Douglasville: closest open option (0.6 h); Columbus retired for 2027 | Q7: GADAL + GAGWI
A8: 1683 | B8: =INDEX(Strength!$B$2:$B$76,MATCH(A8,Strength!$A$2:$A$76,0)) -> Techno Titans | C8: =INDEX(Strength!$C$2:$C$76,MATCH(A8,Strength!$A$2:$A$76,0)) -> Johns Creek | D8: =INDEX(Strength!$U$2:$U$76,MATCH(A8,Strength!$A$2:$A$76,0)) -> 77.227564 | E8: =INDEX(Strength!$V$2:$V$76,MATCH(A8,Strength!$A$2:$A$76,0)) -> 7 | F8: GAGAI | G8: GAGWI | H8: =IF(ISERROR(INDEX('Events 2027'!$C$5:$C$9,MATCH(F8,'Events 2027'!$A$5:$A$9,0))),"",INDEX('Events 2027'!$C$5:$C$9,MATCH(F8,'Events 2027'!$A$5:$A$9,0))) -> 2 | I8: =IF(ISERROR(INDEX('Events 2027'!$C$5:$C$9,MATCH(G8,'Events 2027'!$A$5:$A$9,0))),"",INDEX('Events 2027'!$C$5:$C$9,MATCH(G8,'Events 2027'!$A$5:$A$9,0))) -> 3 | J8: =IF(ISERROR(ABS(I8-H8)),"",ABS(I8-H8)) -> 1 | K8: =IF(ISERROR(INDEX('Drive Times'!$D$12:$I$51,MATCH(C8,'Drive Times'!$A$12:$A$51,0),MATCH(F8,'Drive Times'!$D$11:$I$11,0))),"",INDEX('Drive Times'!$D$12:$I$51,MATCH(C8,'Drive Times'!$A$12:$A$51,0),MATCH(F8,'Drive Times'!$D$11:$I$11,0))) -> 0.74660485 | L8: =IF(ISERROR(INDEX('Drive Times'!$D$12:$I$51,MATCH(C8,'Drive Times'!$A$12:$A$51,0),MATCH(G8,'Drive Times'!$D$11:$I$11,0))),"",INDEX('Drive Times'!$D$12:$I$51,MATCH(C8,'Drive Times'!$A$12:$A$51,0),MATCH(G8,'Drive Times'!$D$11:$I$11,0))) -> 0.46641074 | M8: Gwinnett + Gainesville | N8: 2 | O8: High | P8: Gainesville: returning venue (0.7 h); Lawrenceville: returning venue (0.5 h) | Q8: GADAL + GAGWI
A9: 6829 | B9: =INDEX(Strength!$B$2:$B$76,MATCH(A9,Strength!$A$2:$A$76,0)) -> Ignite Robotics | C9: =INDEX(Strength!$C$2:$C$76,MATCH(A9,Strength!$A$2:$A$76,0)) -> Suwanee | D9: =INDEX(Strength!$U$2:$U$76,MATCH(A9,Strength!$A$2:$A$76,0)) -> 70.796703 | E9: =INDEX(Strength!$V$2:$V$76,MATCH(A9,Strength!$A$2:$A$76,0)) -> 8 | F9: GADAL | G9: GAALB | H9: =IF(ISERROR(INDEX('Events 2027'!$C$5:$C$9,MATCH(F9,'Events 2027'!$A$5:$A$9,0))),"",INDEX('Events 2027'!$C$5:$C$9,MATCH(F9,'Events 2027'!$A$5:$A$9,0))) -> 1 | I9: =IF(ISERROR(INDEX('Events 2027'!$C$5:$C$9,MATCH(G9,'Events 2027'!$A$5:$A$9,0))),"",INDEX('Events 2027'!$C$5:$C$9,MATCH(G9,'Events 2027'!$A$5:$A$9,0))) -> 4 | J9: =IF(ISERROR(ABS(I9-H9)),"",ABS(I9-H9)) -> 3 | K9: =IF(ISERROR(INDEX('Drive Times'!$D$12:$I$51,MATCH(C9,'Drive Times'!$A$12:$A$51,0),MATCH(F9,'Drive Times'!$D$11:$I$11,0))),"",INDEX('Drive Times'!$D$12:$I$51,MATCH(C9,'Drive Times'!$A$12:$A$51,0),MATCH(F9,'Drive Times'!$D$11:$I$11,0))) -> 1.535556 | L9: =IF(ISERROR(INDEX('Drive Times'!$D$12:$I$51,MATCH(C9,'Drive Times'!$A$12:$A$51,0),MATCH(G9,'Drive Times'!$D$11:$I$11,0))),"",INDEX('Drive Times'!$D$12:$I$51,MATCH(C9,'Drive Times'!$A$12:$A$51,0),MATCH(G9,'Drive Times'!$D$11:$I$11,0))) -> 3.3606475 | M9: Dalton + Columbus | N9: 1 | O9: Low | P9: Dalton: returning venue (1.5 h); Albany: attended before 2026 (3.4 h); Columbus retired for 2027; moved by capacity from Dalton/Lawrenceville | Q9: GADAL + GAGWI
A10: 4189 | B10: =INDEX(Strength!$B$2:$B$76,MATCH(A10,Strength!$A$2:$A$76,0)) -> Chargers | C10: =INDEX(Strength!$C$2:$C$76,MATCH(A10,Strength!$A$2:$A$76,0)) -> Jefferson | D10: =INDEX(Strength!$U$2:$U$76,MATCH(A10,Strength!$A$2:$A$76,0)) -> 66.678114 | E10: =INDEX(Strength!$V$2:$V$76,MATCH(A10,Strength!$A$2:$A$76,0)) -> 9 | F10: GAGAI | G10: GAGWI | H10: =IF(ISERROR(INDEX('Events 2027'!$C$5:$C$9,MATCH(F10,'Events 2027'!$A$5:$A$9,0))),"",INDEX('Events 2027'!$C$5:$C$9,MATCH(F10,'Events 2027'!$A$5:$A$9,0))) -> 2 | I10: =IF(ISERROR(INDEX('Events 2027'!$C$5:$C$9,MATCH(G10,'Events 2027'!$A$5:$A$9,0))),"",INDEX('Events 2027'!$C$5:$C$9,MATCH(G10,'Events 2027'!$A$5:$A$9,0))) -> 3 | J10: =IF(ISERROR(ABS(I10-H10)),"",ABS(I10-H10)) -> 1 | K10: =IF(ISERROR(INDEX('Drive Times'!$D$12:$I$51,MATCH(C10,'Drive Times'!$A$12:$A$51,0),MATCH(F10,'Drive Times'!$D$11:$I$11,0))),"",INDEX('Drive Times'!$D$12:$I$51,MATCH(C10,'Drive Times'!$A$12:$A$51,0),MATCH(F10,'Drive Times'!$D$11:$I$11,0))) -> 0.57689351 | L10: =IF(ISERROR(INDEX('Drive Times'!$D$12:$I$51,MATCH(C10,'Drive Times'!$A$12:$A$51,0),MATCH(G10,'Drive Times'!$D$11:$I$11,0))),"",INDEX('Drive Times'!$D$12:$I$51,MATCH(C10,'Drive Times'!$A$12:$A$51,0),MATCH(G10,'Drive Times'!$D$11:$I$11,0))) -> 0.70916816 | M10: Gwinnett + Gainesville | N10: 2 | O10: High | P10: Gainesville: returning venue (0.6 h); Lawrenceville: returning venue (0.7 h) | Q10: GAGAI + GADOU
A11: 4026 | B11: =INDEX(Strength!$B$2:$B$76,MATCH(A11,Strength!$A$2:$A$76,0)) -> Decatur Robotics | C11: =INDEX(Strength!$C$2:$C$76,MATCH(A11,Strength!$A$2:$A$76,0)) -> Decatur | D11: =INDEX(Strength!$U$2:$U$76,MATCH(A11,Strength!$A$2:$A$76,0)) -> 58.60348 | E11: =INDEX(Strength!$V$2:$V$76,MATCH(A11,Strength!$A$2:$A$76,0)) -> 10 | F11: GADAL | G11: GADOU | H11: =IF(ISERROR(INDEX('Events 2027'!$C$5:$C$9,MATCH(F11,'Events 2027'!$A$5:$A$9,0))),"",INDEX('Events 2027'!$C$5:$C$9,MATCH(F11,'Events 2027'!$A$5:$A$9,0))) -> 1 | I11: =IF(ISERROR(INDEX('Events 2027'!$C$5:$C$9,MATCH(G11,'Events 2027'!$A$5:$A$9,0))),"",INDEX('Events 2027'!$C$5:$C$9,MATCH(G11,'Events 2027'!$A$5:$A$9,0))) -> 5 | J11: =IF(ISERROR(ABS(I11-H11)),"",ABS(I11-H11)) -> 4 | K11: =IF(ISERROR(INDEX('Drive Times'!$D$12:$I$51,MATCH(C11,'Drive Times'!$A$12:$A$51,0),MATCH(F11,'Drive Times'!$D$11:$I$11,0))),"",INDEX('Drive Times'!$D$12:$I$51,MATCH(C11,'Drive Times'!$A$12:$A$51,0),MATCH(F11,'Drive Times'!$D$11:$I$11,0))) -> 1.6714503 | L11: =IF(ISERROR(INDEX('Drive Times'!$D$12:$I$51,MATCH(C11,'Drive Times'!$A$12:$A$51,0),MATCH(G11,'Drive Times'!$D$11:$I$11,0))),"",INDEX('Drive Times'!$D$12:$I$51,MATCH(C11,'Drive Times'!$A$12:$A$51,0),MATCH(G11,'Drive Times'!$D$11:$I$11,0))) -> 0.70312585 | M11: Dalton + Columbus | N11: 1 | O11: Low | P11: Dalton: returning venue (1.7 h); Douglasville: closest open option (0.7 h); Columbus retired for 2027; moved by capacity from Dalton/Lawrenceville | Q11: GADAL + GAGWI
A12: 832 | B12: =INDEX(Strength!$B$2:$B$76,MATCH(A12,Strength!$A$2:$A$76,0)) -> OSCAR | C12: =INDEX(Strength!$C$2:$C$76,MATCH(A12,Strength!$A$2:$A$76,0)) -> Roswell | D12: =INDEX(Strength!$U$2:$U$76,MATCH(A12,Strength!$A$2:$A$76,0)) -> 57.284799 | E12: =INDEX(Strength!$V$2:$V$76,MATCH(A12,Strength!$A$2:$A$76,0)) -> 11 | F12: GADAL | G12: GADOU | H12: =IF(ISERROR(INDEX('Events 2027'!$C$5:$C$9,MATCH(F12,'Events 2027'!$A$5:$A$9,0))),"",INDEX('Events 2027'!$C$5:$C$9,MATCH(F12,'Events 2027'!$A$5:$A$9,0))) -> 1 | I12: =IF(ISERROR(INDEX('Events 2027'!$C$5:$C$9,MATCH(G12,'Events 2027'!$A$5:$A$9,0))),"",INDEX('Events 2027'!$C$5:$C$9,MATCH(G12,'Events 2027'!$A$5:$A$9,0))) -> 5 | J12: =IF(ISERROR(ABS(I12-H12)),"",ABS(I12-H12)) -> 4 | K12: =IF(ISERROR(INDEX('Drive Times'!$D$12:$I$51,MATCH(C12,'Drive Times'!$A$12:$A$51,0),MATCH(F12,'Drive Times'!$D$11:$I$11,0))),"",INDEX('Drive Times'!$D$12:$I$51,MATCH(C12,'Drive Times'!$A$12:$A$51,0),MATCH(F12,'Drive Times'!$D$11:$I$11,0))) -> 1.3669289 | L12: =IF(ISERROR(INDEX('Drive Times'!$D$12:$I$51,MATCH(C12,'Drive Times'!$A$12:$A$51,0),MATCH(G12,'Drive Times'!$D$11:$I$11,0))),"",INDEX('Drive Times'!$D$12:$I$51,MATCH(C12,'Drive Times'!$A$12:$A$51,0),MATCH(G12,'Drive Times'!$D$11:$I$11,0))) -> 0.75882023 | M12: Dalton + Columbus | N12: 1 | O12: Low | P12: Dalton: returning venue (1.4 h); Douglasville: closest open option (0.8 h); Columbus retired for 2027; moved by capacity from Dalton/Lawrenceville | Q12: GADAL + GAGWI
A13: 1648 | B13: =INDEX(Strength!$B$2:$B$76,MATCH(A13,Strength!$A$2:$A$76,0)) -> G3 Robotics | C13: =INDEX(Strength!$C$2:$C$76,MATCH(A13,Strength!$A$2:$A$76,0)) -> Atlanta | D13: =INDEX(Strength!$U$2:$U$76,MATCH(A13,Strength!$A$2:$A$76,0)) -> 55.641026 | E13: =INDEX(Strength!$V$2:$V$76,MATCH(A13,Strength!$A$2:$A$76,0)) -> 12 | F13: GADAL | G13: GAALB | H13: =IF(ISERROR(INDEX('Events 2027'!$C$5:$C$9,MATCH(F13,'Events 2027'!$A$5:$A$9,0))),"",INDEX('Events 2027'!$C$5:$C$9,MATCH(F13,'Events 2027'!$A$5:$A$9,0))) -> 1 | I13: =IF(ISERROR(INDEX('Events 2027'!$C$5:$C$9,MATCH(G13,'Events 2027'!$A$5:$A$9,0))),"",INDEX('Events 2027'!$C$5:$C$9,MATCH(G13,'Events 2027'!$A$5:$A$9,0))) -> 4 | J13: =IF(ISERROR(ABS(I13-H13)),"",ABS(I13-H13)) -> 3 | K13: =IF(ISERROR(INDEX('Drive Times'!$D$12:$I$51,MATCH(C13,'Drive Times'!$A$12:$A$51,0),MATCH(F13,'Drive Times'!$D$11:$I$11,0))),"",INDEX('Drive Times'!$D$12:$I$51,MATCH(C13,'Drive Times'!$A$12:$A$51,0),MATCH(F13,'Drive Times'!$D$11:$I$11,0))) -> 1.6567046 | L13: =IF(ISERROR(INDEX('Drive Times'!$D$12:$I$51,MATCH(C13,'Drive Times'!$A$12:$A$51,0),MATCH(G13,'Drive Times'!$D$11:$I$11,0))),"",INDEX('Drive Times'!$D$12:$I$51,MATCH(C13,'Drive Times'!$A$12:$A$51,0),MATCH(G13,'Drive Times'!$D$11:$I$11,0))) -> 2.9879614 | M13: Gwinnett + Albany | N13: 1 | O13: Low | P13: Dalton: attended before 2026 (1.7 h); Albany: returning venue (3.0 h); moved by capacity from Dalton/Lawrenceville | Q13: GADAL + GAGWI
... A75: 1795 | B75: =INDEX(Strength!$B$2:$B$76,MATCH(A75,Strength!$A$2:$A$76,0)) -> Carver Clutch | C75: =INDEX(Strength!$C$2:$C$76,MATCH(A75,Strength!$A$2:$A$76,0)) -> Atlanta | D75: =INDEX(Strength!$U$2:$U$76,MATCH(A75,Strength!$A$2:$A$76,0)) -> 0 | E75: =INDEX(Strength!$V$2:$V$76,MATCH(A75,Strength!$A$2:$A$76,0)) -> 74 | F75: GAGAI | G75: GAGWI | H75: =IF(ISERROR(INDEX('Events 2027'!$C$5:$C$9,MATCH(F75,'Events 2027'!$A$5:$A$9,0))),"",INDEX('Events 2027'!$C$5:$C$9,MATCH(F75,'Events 2027'!$A$5:$A$9,0))) -> 2 | I75: =IF(ISERROR(INDEX('Events 2027'!$C$5:$C$9,MATCH(G75,'Events 2027'!$A$5:$A$9,0))),"",INDEX('Events 2027'!$C$5:$C$9,MATCH(G75,'Events 2027'!$A$5:$A$9,0))) -> 3 | J75: =IF(ISERROR(ABS(I75-H75)),"",ABS(I75-H75)) -> 1 | K75: =IF(ISERROR(INDEX('Drive Times'!$D$12:$I$51,MATCH(C75,'Drive Times'!$A$12:$A$51,0),MATCH(F75,'Drive Times'!$D$11:$I$11,0))),"",INDEX('Drive Times'!$D$12:$I$51,MATCH(C75,'Drive Times'!$A$12:$A$51,0),MATCH(F75,'Drive Times'!$D$11:$I$11,0))) -> 1.140498 | L75: =IF(ISERROR(INDEX('Drive Times'!$D$12:$I$51,MATCH(C75,'Drive Times'!$A$12:$A$51,0),MATCH(G75,'Drive Times'!$D$11:$I$11,0))),"",INDEX('Drive Times'!$D$12:$I$51,MATCH(C75,'Drive Times'!$A$12:$A$51,0),MATCH(G75,'Drive Times'!$D$11:$I$11,0))) -> 0.72301357 | M75: Gwinnett + Gainesville | N75: 2 | O75: Medium | P75: Gainesville: returning venue (1.1 h); Lawrenceville: returning venue (0.7 h) | Q75: GAGWI + GADOU
A77: Blue event codes are model outputs you can override; weeks, drive times, densities and the planner recalculate. Codes: GADAL Dalton W1, GAGAI Gainesville W2, GAGWI Gwinnett W3, GAALB Albany W4, GADOU Douglasville W5.

Sheet Fields 2027
A1: Predicted fields — cell shows the team's blended strength if forecast to attend (live from Forecast 2027)
A2: Team | B2: Strength rank | C2: Strength | D2: GADAL (Dalton W1) | E2: GAGAI (Gainesville W2) | F2: GAGWI (Lawrenceville W3) | G2: GAALB (Albany W4) | H2: GADOU (Douglasville W5)
A3: ='Forecast 2027'!A2 -> 1833 | B3: ='Forecast 2027'!E2 -> 1 | C3: ='Forecast 2027'!D2 -> 100 | D3: =IF(OR('Forecast 2027'!$F2="GADAL",'Forecast 2027'!$G2="GADAL"),'Forecast 2027'!$D2,"") | E3: =IF(OR('Forecast 2027'!$F2="GAGAI",'Forecast 2027'!$G2="GAGAI"),'Forecast 2027'!$D2,"") -> 100 | F3: =IF(OR('Forecast 2027'!$F2="GAGWI",'Forecast 2027'!$G2="GAGWI"),'Forecast 2027'!$D2,"") -> 100 | G3: =IF(OR('Forecast 2027'!$F2="GAALB",'Forecast 2027'!$G2="GAALB"),'Forecast 2027'!$D2,"") | H3: =IF(OR('Forecast 2027'!$F2="GADOU",'Forecast 2027'!$G2="GADOU"),'Forecast 2027'!$D2,"")
A4: ='Forecast 2027'!A3 -> 4188 | B4: ='Forecast 2027'!E3 -> 2 | C4: ='Forecast 2027'!D3 -> 93.195971 | D4: =IF(OR('Forecast 2027'!$F3="GADAL",'Forecast 2027'!$G3="GADAL"),'Forecast 2027'!$D3,"") | E4: =IF(OR('Forecast 2027'!$F3="GAGAI",'Forecast 2027'!$G3="GAGAI"),'Forecast 2027'!$D3,"") | F4: =IF(OR('Forecast 2027'!$F3="GAGWI",'Forecast 2027'!$G3="GAGWI"),'Forecast 2027'!$D3,"") | G4: =IF(OR('Forecast 2027'!$F3="GAALB",'Forecast 2027'!$G3="GAALB"),'Forecast 2027'!$D3,"") -> 93.195971 | H4: =IF(OR('Forecast 2027'!$F3="GADOU",'Forecast 2027'!$G3="GADOU"),'Forecast 2027'!$D3,"") -> 93.195971
A5: ='Forecast 2027'!A4 -> 1002 | B5: ='Forecast 2027'!E4 -> 3 | C5: ='Forecast 2027'!D4 -> 93.014811 | D5: =IF(OR('Forecast 2027'!$F4="GADAL",'Forecast 2027'!$G4="GADAL"),'Forecast 2027'!$D4,"") -> 93.014811 | E5: =IF(OR('Forecast 2027'!$F4="GAGAI",'Forecast 2027'!$G4="GAGAI"),'Forecast 2027'!$D4,"") | F5: =IF(OR('Forecast 2027'!$F4="GAGWI",'Forecast 2027'!$G4="GAGWI"),'Forecast 2027'!$D4,"") | G5: =IF(OR('Forecast 2027'!$F4="GAALB",'Forecast 2027'!$G4="GAALB"),'Forecast 2027'!$D4,"") -> 93.014811 | H5: =IF(OR('Forecast 2027'!$F4="GADOU",'Forecast 2027'!$G4="GADOU"),'Forecast 2027'!$D4,"")
A6: ='Forecast 2027'!A5 -> 6919 | B6: ='Forecast 2027'!E5 -> 4 | C6: ='Forecast 2027'!D5 -> 86.620879 | D6: =IF(OR('Forecast 2027'!$F5="GADAL",'Forecast 2027'!$G5="GADAL"),'Forecast 2027'!$D5,"") -> 86.620879 | E6: =IF(OR('Forecast 2027'!$F5="GAGAI",'Forecast 2027'!$G5="GAGAI"),'Forecast 2027'!$D5,"") | F6: =IF(OR('Forecast 2027'!$F5="GAGWI",'Forecast 2027'!$G5="GAGWI"),'Forecast 2027'!$D5,"") | G6: =IF(OR('Forecast 2027'!$F5="GAALB",'Forecast 2027'!$G5="GAALB"),'Forecast 2027'!$D5,"") -> 86.620879 | H6: =IF(OR('Forecast 2027'!$F5="GADOU",'Forecast 2027'!$G5="GADOU"),'Forecast 2027'!$D5,"")
A7: ='Forecast 2027'!A6 -> 1771 | B7: ='Forecast 2027'!E6 -> 5 | C7: ='Forecast 2027'!D6 -> 84.194139 | D7: =IF(OR('Forecast 2027'!$F6="GADAL",'Forecast 2027'!$G6="GADAL"),'Forecast 2027'!$D6,"") | E7: =IF(OR('Forecast 2027'!$F6="GAGAI",'Forecast 2027'!$G6="GAGAI"),'Forecast 2027'!$D6,"") | F7: =IF(OR('Forecast 2027'!$F6="GAGWI",'Forecast 2027'!$G6="GAGWI"),'Forecast 2027'!$D6,"") -> 84.194139 | G7: =IF(OR('Forecast 2027'!$F6="GAALB",'Forecast 2027'!$G6="GAALB"),'Forecast 2027'!$D6,"") -> 84.194139 | H7: =IF(OR('Forecast 2027'!$F6="GADOU",'Forecast 2027'!$G6="GADOU"),'Forecast 2027'!$D6,"")
A8: ='Forecast 2027'!A7 -> 2974 | B8: ='Forecast 2027'!E7 -> 6 | C8: ='Forecast 2027'!D7 -> 82.097468 | D8: =IF(OR('Forecast 2027'!$F7="GADAL",'Forecast 2027'!$G7="GADAL"),'Forecast 2027'!$D7,"") -> 82.097468 | E8: =IF(OR('Forecast 2027'!$F7="GAGAI",'Forecast 2027'!$G7="GAGAI"),'Forecast 2027'!$D7,"") | F8: =IF(OR('Forecast 2027'!$F7="GAGWI",'Forecast 2027'!$G7="GAGWI"),'Forecast 2027'!$D7,"") | G8: =IF(OR('Forecast 2027'!$F7="GAALB",'Forecast 2027'!$G7="GAALB"),'Forecast 2027'!$D7,"") | H8: =IF(OR('Forecast 2027'!$F7="GADOU",'Forecast 2027'!$G7="GADOU"),'Forecast 2027'!$D7,"") -> 82.097468
